Workbook

Sheet Fotografia
A1: Equipe | B1: 1 - Mês | C1: 2 - Meses | D1: 3 - Meses | E1: Cliente Novo | F1: Comprando | G1: Total Geral
A2: F_Juazeiro | B2: 82 | C2: 30 | D2: 22 | E2: 0 | F2: 106 | G2: 240
A3: F_Maranhão | B3: 7 | C3: 1 | D3: 6 | E3: 0 | F3: 111 | G3: 125
A4: F_Mossoró | B4: 13 | C4: 4 | D4: 18 | E4: 0 | F4: 22 | G4: 57
A5: F_Pernambuco_AS | B5: 17 | C5: 0 | D5: 1 | F5: 5 | G5: 23
A6: F_Pernambuco_PB | B6: 1 | C6: 0 | D6: 5 | F6: 0 | G6: 6
A7: F_Pernambuco_VA | B7: 13 | C7: 3 | D7: 10 | E7: 0 | F7: 9 | G7: 35
A8: F_Sobral | B8: 243 | C8: 52 | D8: 77 | E8: 4 | F8: 308 | G8: 684
A9: F_Teresina | B9: 84 | C9: 7 | D9: 40 | F9: 111 | G9: 242
A10: M_Capital | B10: 337 | C10: 69 | D10: 113 | E10: 1 | F10: 371 | G10: 891
A11: M_Interior | B11: 31 | C11: 4 | D11: 14 | E11: 1 | F11: 133 | G11: 183
A12: M_Nacionais | B12: 73 | C12: 7 | D12: 24 | E12: 0 | F12: 355 | G12: 459
A13: M_Regionais | B13: 67 | C13: 0 | D13: 2 | E13: 0 | F13: 272 | G13: 341
A14: Marujinho | B14: 29 | C14: 7 | D14: 14 | F14: 335 | G14: 385
A15: Telemarketing | B15: 69 | C15: 23 | D15: 14 | E15: 2 | F15: 110 | G15: 218
A16: Total Geral | B16: 1066 | C16: 207 | D16: 360 | E16: 8 | F16: 2248 | G16: 3889

Sheet Resumo Clientes
A1: ativo | B1: Y
A2: Status Equipamento | B2: (Vários itens)
A4: supervisor | B4: vendedor | C4: cod_cliente | D4: nome_fantasia | E4: data_cadastro | F4: Soma de Horizontal | G4: Soma de Vertical | H4: Soma de Total Equipamento
A5: F_Juazeiro | B5: Jefferson | C5: C03266 | D5: FARMACIA SANTA LUZIA | E5: 45688 | F5: 0 | G5: 0 | H5: 0
A6: F_Juazeiro | B6: Jefferson | C6: C03329 | D6: RAIMUNDO JOSE CRUZ (JAMACARU) | E6: 45691 | F6: 0 | G6: 0 | H6: 0
A7: F_Juazeiro | B7: Jefferson | C7: C03361 | D7: VICTOR HUGO DOS SANTOS ME | E7: 45691 | F7: 0 | G7: 0 | H7: 0
A8: F_Juazeiro | B8: Jefferson | C8: C04908 | D8: MERCADINHO SIEBRA | E8: 45691 | F8: 0 | G8: 0 | H8: 0
A9: F_Juazeiro | B9: Jefferson | C9: C05610 | D9: DROGAJACK | E9: 45691 | F9: 1 | G9: 0 | H9: 1
A10: F_Juazeiro | B10: Jefferson | C10: C08876 | D10: POSTO SANTO EXPEDITO | E10: 45691 | F10: 1 | G10: 0 | H10: 1
A11: F_Juazeiro | B11: Jefferson | C11: C08998 | D11: FARMACIA CLEIA | E11: 45691 | F11: 1 | G11: 0 | H11: 1
A12: F_Juazeiro | B12: Jefferson | C12: C09163 | D12: MERCANTIL GRANJEIRO | E12: 45691 | F12: 1 | G12: 0 | H12: 1
A13: F_Juazeiro | B13: Jefferson | C13: C11192 | D13: BOTECO DO RIQUIM | E13: 45691 | F13: 0 | G13: 0 | H13: 0
A14: F_Juazeiro | B14: Jefferson | C14: C11492 | D14: BREJO PARK | E14: 45691 | F14: 0 | G14: 0 | H14: 0
A15: F_Juazeiro | B15: Jefferson | C15: C11926 | D15: CHURRASCARIA CAICARA | E15: 45691 | F15: 1 | G15: 0 | H15: 1
A16: F_Juazeiro | B16: Jefferson | C16: C13387 | D16: BARATO ATACAREJO | E16: 45691 | F16: 0 | G16: 0 | H16: 0
... A2092: Telemarketing | B2092: Sujeiras TLM | C2092: C08325 | D2092: ADRIANA DA SILVA | E2092: 45691 | F2092: 0 | G2092: 0 | H2092: 0

Sheet 2 e 3 Meses_SC
A1: Supervisor | B1: Vendedor | C1: Cod_Cliente | D1: Nome_Fantasia | E1: Data_Cadastro | F1: Data_Ultima_Compra | G1: Status Equipamento | H1: Horizontal | I1: Vertical | J1: Total Equipamento | K1: Chamado | L1: Data_Abertura | M1: Data_Encerramento | N1: Status | O1: Tratativa | P1: Prazo | Q1: Responsável Direto | R1: Status2 | S1: Total Equipamento Atual
A2: F_Juazeiro | B2: Jefferson | C2: C05610 | D2: DROGAJACK | E2: 03/02/2025 | F2: 18/02/2026 | G2: 2 - Meses | H2: 1 | I2: 0 | J2: 1 | O2: SEM TRATATIVA | P2: 17/04/2026 | Q2: COMERCIAL | R2: PENDENTE | S2: 1
A3: F_Juazeiro | B3: Jefferson | C3: C08876 | D3: POSTO SANTO EXPEDITO | E3: 03/02/2025 | F3: 19/02/2026 | G3: 2 - Meses | H3: 1 | I3: 0 | J3: 1 | O3: POSITIVADO | P3: 17/04/2026 | Q3: COMERCIAL | R3: CONCLUIDO | S3: 1
A4: F_Juazeiro | B4: Morgana | C4: C22919 | D4: FARMACIAS GENTIL | E4: 03/02/2025 | F4: 26/01/2026 | G4: 3 - Meses | H4: 1 | I4: 0 | J4: 1 | O4: RECOLHIDO (NÃO POSSUI CHAMADO) | Q4: COMERCIAL | R4: PENDENTE | S4: 1
A5: F_Juazeiro | B5: Jefferson | C5: C09163 | D5: MERCANTIL GRANJEIRO | E5: 03/02/2025 | F5: 23/02/2026 | G5: 2 - Meses | H5: 1 | I5: 0 | J5: 1 | O5: POSITIVADO | P5: 17/04/2026 | Q5: COMERCIAL | R5: CONCLUIDO | S5: 1
A6: F_Juazeiro | B6: Jefferson | C6: C11926 | D6: CHURRASCARIA CAICARA | E6: 03/02/2025 | F6: 06/02/2026 | G6: 2 - Meses | H6: 1 | I6: 0 | J6: 1 | O6: POSITIVADO | P6: 17/04/2026 | Q6: COMERCIAL | R6: CONCLUIDO | S6: 1
A7: F_Juazeiro | B7: Jefferson | C7: C14885 | D7: BAR DE ELIANA | E7: 03/02/2025 | F7: 23/02/2026 | G7: 2 - Meses | H7: 1 | I7: 0 | J7: 1 | O7: SEM TRATATIVA | P7: 17/04/2026 | Q7: COMERCIAL | R7: PENDENTE | S7: 1
A8: F_Juazeiro | B8: Jefferson | C8: C15431 | D8: MERCADINHO DO MIGUEL | E8: 03/02/2025 | F8: 23/02/2026 | G8: 2 - Meses | H8: 1 | I8: 0 | J8: 1 | O8: POSITIVADO | P8: 17/04/2026 | Q8: COMERCIAL | R8: CONCLUIDO | S8: 1
A9: F_Juazeiro | B9: Jefferson | C9: C17751 | D9: CHACARA JM | E9: 03/02/2025 | F9: 20/02/2026 | G9: 2 - Meses | H9: 2 | I9: 0 | J9: 2 | O9: POSITIVADO | P9: 17/04/2026 | Q9: COMERCIAL | R9: CONCLUIDO | S9: 2
A10: F_Juazeiro | B10: Jefferson | C10: C18098 | D10: AGUAS FINAS BALNEARIO | E10: 03/02/2025 | F10: 12/02/2026 | G10: 2 - Meses | H10: 1 | I10: 0 | J10: 1 | O10: SEM TRATATIVA | P10: 17/04/2026 | Q10: COMERCIAL | R10: PENDENTE | S10: 1
A11: F_Juazeiro | B11: Jefferson | C11: C19137 | D11: MERCADINHO CLEOMARCIO ARMARINHO PM | E11: 03/02/2025 | F11: - | G11: 3 - Meses | H11: 1 | I11: 0 | J11: 1 | K11: ALTERAÇÃO CADASTRAL | L11: 14/04/2026 | M11: 46128 | N11: Encerrado | O11: ATUALIZAÇÃO CADASTRAL | P11: 46128 | Q11: MANUTENÇÃO | R11: CONCLUIDO | S11: 0
A12: F_Juazeiro | B12: Luan | C12: C24490 | D12: MARCONE SUPERMERCADO | E12: 03/02/2025 | F12: 04/04/2025 | G12: 3 - Meses | H12: 1 | I12: 0 | J12: 1 | O12: RECOLHIDO | Q12: MANUTENÇÃO | R12: PENDENTE | S12: 1
A13: F_Juazeiro | B13: Jefferson | C13: C25686 | D13: JULIA CRISTINA DE SA RORIZ MIRANDA | E13: 31/03/2025 | F13: 11/02/2026 | G13: 2 - Meses | H13: 1 | I13: 0 | J13: 1 | O13: POSITIVADO | P13: 17/04/2026 | Q13: COMERCIAL | R13: CONCLUIDO | S13: 1
A14: F_Juazeiro | B14: Jefferson | C14: C26788 | D14: WENDELL ALVES DA COSTA | E14: 01/07/2025 | F14: 13/04/2026 | G14: 2 - Meses | H14: 1 | I14: 0 | J14: 1 | O14: POSITIVADO | P14: 13/04/2026 | Q14: COMERCIAL | R14: CONCLUIDO | S14: 1
A15: F_Juazeiro | B15: Jefferson | C15: C28206 | D15: BALNEARIO RECANTO DO SOSSEGO | E15: 03/10/2025 | F15: 19/02/2026 | G15: 2 - Meses | H15: 1 | I15: 0 | J15: 1 | O15: POSITIVADO | P15: 17/04/2026 | Q15: COMERCIAL | R15: CONCLUIDO | S15: 1
A16: F_Juazeiro | B16: Luan | C16: C04806 | D16: JOSE SERGIO RODRIGUES CUNHA | E16: 03/02/2025 | F16: 24/02/2026 | G16: 2 - Meses | H16: 1 | I16: 0 | J16: 1 | O16: SEM TRATATIVA | P16: 17/04/2026 | Q16: COMERCIAL | R16: PENDENTE | S16: 1
A17: F_Juazeiro | B17: Luan | C17: C05139 | D17: REZORT LAZER DIVERSOES | E17: 03/02/2025 | F17: 10/02/2026 | G17: 2 - Meses | H17: 2 | I17: 0 | J17: 2 | O17: POSITIVADO | P17: 17/04/2026 | Q17: COMERCIAL | R17: CONCLUIDO | S17: 2
A18: F_Juazeiro | B18: Luan | C18: C05993 | D18: POUSADA MEDEIROS | E18: 03/02/2025 | F18: 19/12/2025 | G18: 3 - Meses | H18: 1 | I18: 0 | J18: 1 | O18: POSITIVADO | Q18: COMERCIAL | R18: CONCLUIDO | S18: 1
A19: F_Juazeiro | B19: Luan | C19: C10288 | D19: FARMACIA BOA ESPERANCA | E19: 03/02/2025 | F19: 30/01/2026 | G19: 2 - Meses | H19: 1 | I19: 0 | J19: 1 | O19: SEM TRATATIVA | P19: 17/04/2026 | Q19: COMERCIAL | R19: PENDENTE | S19: 1
A20: F_Juazeiro | B20: Luciano | C20: C19030 | D20: EMPORIO DAS AGUAS | E20: 03/02/2025 | F20: 30/01/2026 | G20: 3 - Meses | H20: 1 | I20: 0 | J20: 1 | K20: RECOLHA | L20: 14/04/2026 | M20: 15/04/2026 | N20: Encerrado | O20: EQUIPAMENTO RECOLHIDO | P20: 15/04/2026 | Q20: MANUTENÇÃO | R20: CONCLUIDO | S20: 0
A21: F_Juazeiro | B21: Luan | C21: C13405 | D21: TICO DA BODEGA | E21: 03/02/2025 | F21: 16/01/2026 | G21: 3 - Meses | H21: 1 | I21: 0 | J21: 1 | O21: VAI POSITIVAR | Q21: COMERCIAL | R21: PENDENTE | S21: 1
A22: F_Juazeiro | B22: Luan | C22: C14049 | D22: LANCHONETE MAIS DELICIA | E22: 03/02/2025 | F22: 13/04/2026 | G22: 2 - Meses | H22: 1 | I22: 0 | J22: 1 | O22: POSITIVADO | P22: 13/04/2026 | Q22: COMERCIAL | R22: CONCLUIDO | S22: 1
A23: F_Juazeiro | B23: Luan | C23: C14705 | D23: BAR DO LUCIANO | E23: 03/02/2025 | F23: 05/11/2025 | G23: 3 - Meses | H23: 1 | I23: 0 | J23: 1 | O23: VAI POSITIVAR | Q23: COMERCIAL | R23: PENDENTE | S23: 1
A24: F_Juazeiro | B24: Luan | C24: C15364 | D24: D M SUPERMERCADO | E24: 03/02/2025 | F24: 13/02/2026 | G24: 2 - Meses | H24: 1 | I24: 0 | J24: 1 | O24: SEM TRATATIVA | P24: 17/04/2026 | Q24: COMERCIAL | R24: PENDENTE | S24: 1
A25: F_Juazeiro | B25: Luan | C25: C20963 | D25: LANCHONETE PARADA OBRIGATORIA | E25: 31/01/2025 | F25: 27/02/2026 | G25: 2 - Meses | H25: 1 | I25: 0 | J25: 1 | O25: SEM TRATATIVA | P25: 17/04/2026 | Q25: COMERCIAL | R25: PENDENTE | S25: 1
A26: F_Juazeiro | B26: Luciano | C26: C25071 | D26: MERCADINHO PEIXOTO | E26: 03/02/2025 | F26: 29/01/2026 | G26: 3 - Meses | H26: 1 | I26: 0 | J26: 1 | O26: SEM TRATATIVA | Q26: COMERCIAL | R26: PENDENTE | S26: 1
A27: F_Juazeiro | B27: Luan | C27: C21220 | D27: ICE CREAM | E27: 03/02/2025 | F27: 09/04/2026 | G27: 3 - Meses | H27: 1 | I27: 0 | J27: 1 | O27: POSITIVADO | P27: 09/04/2026 | Q27: COMERCIAL | R27: CONCLUIDO | S27: 1
A28: F_Juazeiro | B28: Luan | C28: C22971 | D28: BAR DO NELDIM | E28: 03/02/2025 | F28: 16/04/2026 | G28: 2 - Meses | H28: 1 | I28: 0 | J28: 1 | O28: POSITIVADO | P28: 16/04/2026 | Q28: COMERCIAL | R28: CONCLUIDO | S28: 1
A29: F_Juazeiro | B29: Luan | C29: C23117 | D29: BAR DOS AMIGOS | E29: 03/02/2025 | F29: 20/01/2026 | G29: 3 - Meses | H29: 1 | I29: 0 | J29: 1 | O29: VAI POSITIVAR | Q29: COMERCIAL | R29: PENDENTE | S29: 1
A30: F_Juazeiro | B30: Luan | C30: C23789 | D30: BALNEARIO LUIZ FILHO | E30: 03/02/2025 | F30: 14/04/2026 | G30: 3 - Meses | H30: 1 | I30: 0 | J30: 1 | O30: POSITIVADO | P30: 14/04/2026 | Q30: COMERCIAL | R30: CONCLUIDO | S30: 1
A31: F_Juazeiro | B31: Luciano | C31: C26016 | D31: MERCEARIA DA JUCI | E31: 14/04/2025 | F31: 28/11/2025 | G31: 3 - Meses | H31: 1 | I31: 0 | J31: 1 | K31: RECOLHA | L31: 14/04/2026 | M31: 15/04/2026 | N31: Encerrado | O31: EQUIPAMENTO RECOLHIDO | P31: 15/04/2026 | Q31: MANUTENÇÃO | R31: CONCLUIDO | S31: 0
A32: F_Juazeiro | B32: Luan | C32: C24795 | D32: RENATO A DE SOUZA | E32: 03/02/2025 | F32: 15/04/2026 | G32: 2 - Meses | H32: 1 | I32: 0 | J32: 1 | O32: POSITIVADO | P32: 15/04/2026 | Q32: COMERCIAL | R32: CONCLUIDO | S32: 1
A33: F_Juazeiro | B33: Luan | C33: C24863 | D33: GELADAO DO CARNEIRINHO | E33: 03/02/2025 | F33: 15/04/2026 | G33: 3 - Meses | H33: 1 | I33: 0 | J33: 1 | O33: POSITIVADO | P33: 15/04/2026 | Q33: COMERCIAL | R33: CONCLUIDO | S33: 1
A34: F_Juazeiro | B34: Luan | C34: C28045 | D34: J CLEANTO SUPERMERCADO | E34: 22/09/2025 | F34: 26/02/2026 | G34: 2 - Meses | H34: 0 | I34: 1 | J34: 1 | O34: POSITIVADO | P34: 17/04/2026 | Q34: COMERCIAL | R34: CONCLUIDO | S34: 1
A35: F_Juazeiro | B35: Luan | C35: C28269 | D35: MOMENTOS GELADOS | E35: 09/10/2025 | F35: 14/04/2026 | G35: 2 - Meses | H35: 2 | I35: 0 | J35: 2 | O35: POSITIVADO | P35: 14/04/2026 | Q35: COMERCIAL | R35: CONCLUIDO | S35: 2
A36: F_Juazeiro | B36: Luciano | C36: C09335 | D36: POINT DO SORVETE | E36: 03/02/2025 | F36: 30/01/2026 | G36: 3 - Meses | H36: 1 | I36: 0 | J36: 1 | O36: VAI POSITIVAR | Q36: COMERCIAL | R36: PENDENTE | S36: 1
A37: F_Juazeiro | B37: Luciano | C37: C10158 | D37: POINT DO ACAI | E37: 03/02/2025 | F37: 21/02/2026 | G37: 2 - Meses | H37: 1 | I37: 0 | J37: 1 | O37: SEM TRATATIVA | P37: 17/04/2026 | Q37: COMERCIAL | R37: PENDENTE | S37: 1
A38: F_Juazeiro | B38: Luciano | C38: C10647 | D38: P & E VARIEDADES | E38: 03/02/2025 | F38: 23/02/2026 | G38: 2 - Meses | H38: 2 | I38: 0 | J38: 2 | O38: SEM TRATATIVA | P38: 17/04/2026 | Q38: COMERCIAL | R38: PENDENTE | S38: 2
A39: F_Juazeiro | B39: Jefferson | C39: C08998 | D39: FARMACIA CLEIA | E39: 03/02/2025 | F39: 14/11/2025 | G39: 3 - Meses | H39: 1 | I39: 0 | J39: 1 | K39: RECOLHA | L39: 13/04/2026 | N39: ABERTO | O39: RECOLHER | Q39: MANUTENÇÃO | R39: PENDENTE | S39: 1
A40: F_Juazeiro | B40: Luciano | C40: C19212 | D40: LIP PIZZAS E MASSAS | E40: 03/02/2025 | F40: 13/01/2026 | G40: 3 - Meses | H40: 1 | I40: 0 | J40: 1 | O40: VAI POSITIVAR | Q40: COMERCIAL | R40: PENDENTE | S40: 1
...

Sheet dCliente
A1: supervisor | B1: cod_supervisor | C1: vendedor | D1: cod_vendedor | E1: promotor | F1: cod_promotor | G1: rede | H1: cod_cliente | I1: nome_fantasia | J1: razao_social | K1: cod_segmento | L1: segmento | M1: cod_canal | N1: canal | O1: tipo_cadastro | P1: ativo | Q1: bairro | R1: cidade | S1: estado | T1: pais | U1: data_cadastro | V1: data_inativacao | W1: cnpj | X1: dia_roteiro | Y1: periodo_visita | Z1: desc.pontual | AA1: utilizacao | AB1: prazo_pagamento | AC1: Banco | AD1: lista_preco | AE1: cep | AF1: latitude | AG1: longitude | AH1: bloqueio_inadimplente | AI1: spc | AJ1: credito_limitado | AK1: saldo_conta | AL1: limite_credito | AM1: Horizontal | AN1: Vertical | AO1: Total Equipamento | AP1: Venda_MesAnt3 | AQ1: Venda_MesAnt2 | AR1: Venda_MesAnt | AS1: Venda_MesAtual | AT1: Positivado_MesAnt3 > 300 | AU1: Positivado_MesAnt2 > 300 | AV1: Positivado_MesAnt > 300 | AW1: Positivado_MesAtual > 300 | AX1: MetaPositivaçãoMesAnt3 | AY1: MetaPositivaçãoMesAnt2 | AZ1: MetaPositivaçãoMesAnt | BA1: MetaPositivaçãoMesAtual | BB1: MetaGiro_MesAnt3 | BC1: MetaGiro_MesAnt2 | BD1: MetaGiro_MesAnt | BE1: MetaGiro_MesAtual | BF1: RealGiro_MesAnt3 | BG1: RealGiro_MesAnt2 | BH1: RealGiro_MesAnt | BI1: RealGiro_MesAtual | BJ1: Giro_MesAnt3 | BK1: Giro_MesAnt2 | BL1: Giro_MesAnt | BM1: Giro_MesAtual | BN1: Real_Giro_MesAnt3 | BO1: Real_Giro_MesAnt2 | BP1: Real_Giro_MesAnt | BQ1: Real_Giro_MesAtual | BR1: Atg_Giro_MesAnt3 | BS1: Atg_Giro_MesAnt2 | BT1: Atg_Giro_MesAnt | BU1: Atg_Giro_MesAtual | BV1: Ticket Médio 3M | BW1: Sem_compra_vertical_MesAnt3 | BX1: Sem_compra_vertacal_MesAnt2 | BY1: Sem_compra_vertical_MesAnt | BZ1: Sem_compra_vertical_MesAtual | CA1: Gerência | CB1: Canal_RCA | CC1: Canal_Id | CD1: latitude_Cliente | CE1: longitude_cliente | CF1: Meses S/ Compra | CG1: Status Equipamento | CH1: ClassificaçãoId | CI1: ClassificaçãoName
A2: M_Capital | B2: 1441 | C2: Alexsanderson | D2: 1061 | G2: CLIENTES | H2: C00010 | I2: FARMACIA OPCAO | J2: FARMACIA OPCAO LTDA | K2: 11 | M2: 7 | N2: PEQUENO VAREJO | O2: C | P2: Y | Q2: Dionisio Torres | R2: Fortaleza | S2: CE | T2: BR | U2: 45688 | X2: Ter | Y2: Q2 | AA2: Revenda | AB2: 7 dias | AC2: BLT-ITAÚ 130681 | AD2: CAPITAL CE | AE2: 60135-102 | AF2: -3.745251 | AG2: -38.5035444 | AH2: Sim | AI2: Não | AJ2: Sim | AK2: 1973.96 | AL2: 1100 | AM2: 0 | AN2: 0 | AO2: 0 | AP2: 0 | AQ2: 0 | AR2: 0 | AS2: 0 | AT2: 0 | AU2: 0 | AV2: 0 | AW2: 0 | AX2: 1 | AY2: 1 | AZ2: 1 | BA2: 1 | BV2: 0 | BW2: 0 | BX2: 0 | BY2: 0 | BZ2: 0 | CA2: CE | CB2: Varejo | CC2: Vendedor/Varejo | CD2: -3745251 | CE2: -38503544 | CF2: 3 | CG2: 3 - Meses | CH2: 0 - S/COMPRA | CI2: 0 - <= 0
A3: M_Capital | B3: 1441 | C3: Alexsanderson | D3: 1061 | G3: CLIENTES | H3: C00043 | I3: SWEET MIMOS (LEIRIE DE ANDRADE) | J3: SWEET MIMOS COM DE UTILIDADES LTDA | K3: 24 | M3: 7 | N3: PEQUENO VAREJO | O3: C | P3: Y | Q3: JOAQUIM TAVORA | R3: FORTALEZA | S3: CE | T3: BR | U3: 45688 | X3: Ter | Y3: Q2 | AA3: Revenda | AB3: 15 dias | AC3: BLT-SOF | AD3: CAPITAL CE | AE3: 60115-001 | AF3: -3.7388948 | AG3: -38.5150676 | AH3: Sim | AI3: Não | AJ3: Não | AK3: 0 | AL3: 800 | AM3: 0 | AN3: 0 | AO3: 0 | AP3: 0 | AQ3: 0 | AR3: 0 | AS3: 0 | AT3: 0 | AU3: 0 | AV3: 0 | AW3: 0 | AX3: 1 | AY3: 1 | AZ3: 1 | BA3: 1 | BV3: 0 | BW3: 0 | BX3: 0 | BY3: 0 | BZ3: 0 | CA3: CE | CB3: Varejo | CC3: Vendedor/Varejo | CD3: -37388948 | CE3: -38515067 | CF3: 3 | CG3: 3 - Meses | CH3: 0 - S/COMPRA | CI3: 0 - <= 0
A4: M_Nacionais | B4: 12 | C4: Lettelie | D4: 996 | G4: NOVA REDE | H4: C00074 | I4: MERCADINHO ARCO VERDE | J4: JOAO BATISTA DA S GEN ALIM LTDA | K4: 1 | M4: 1 | N4: AUTOSSERVIÇO REGIONAL | O4: C | P4: Y | Q4: Jardim Petropolis | R4: Fortaleza | S4: CE | T4: BR | U4: 45688 | X4: Qua | Y4: Semanal | AA4: Revenda | AB4: 15 dias | AC4: BLT-ITAÚ 130681 | AD4: AUTOSSERVIÇO CE | AE4: 60332-100 | AF4: -3.7027092 | AG4: -38.57606 | AH4: Sim | AI4: Não | AJ4: Não | AK4: 0 | AL4: 1350 | AM4: 0 | AN4: 0 | AO4: 0 | AP4: 0 | AQ4: 0 | AR4: 0 | AS4: 0 | AT4: 0 | AU4: 0 | AV4: 0 | AW4: 0 | AX4: 1 | AY4: 1 | AZ4: 1 | BA4: 1 | BV4: 0 | BW4: 0 | BX4: 0 | BY4: 0 | BZ4: 0 | CA4: CE | CB4: AS | CC4: Vendedor/AS | CD4: -37027092 | CE4: -3857606 | CF4: 3 | CG4: 3 - Meses | CH4: 0 - S/COMPRA | CI4: 0 - <= 0
A5: Marujinho | B5: 143 | C5: Jacilane | D5: 1040 | G5: DISTRI CAPITAL MARUJ | H5: C00133 | I5: ELENITA GOMES | J5: ELENITA GOMES DA COSTA | K5: 9 | M5: 6 | N5: DISTRIBUIDORES | O5: C | P5: Y | Q5: ITAMBE II | R5: CAUCAIA | S5: CE | T5: BR | U5: 45688 | X5: Qui | Y5: Semanal | AA5: Revenda | AB5: a vista | AC5: BLT-SANT 804-1 | AD5: MARUJINHO DIST CAPITAL DUPLICATA | AE5: 61602-650 | AF5: -3.728651 | AG5: -38.646193 | AH5: Sim | AI5: Não | AJ5: Sim | AK5: 3723.69 | AL5: 0 | AM5: 2 | AN5: 0 | AO5: 2 | AP5: 0 | AQ5: 436.36 | AR5: 0 | AS5: 0 | AT5: 0 | AU5: 1 | AV5: 0 | AW5: 0 | AX5: 1 | AY5: 1 | AZ5: 1 | BA5: 1 | BB5: 1200 | BC5: 1200 | BD5: 1200 | BE5: 1200 | BF5: 0 | BG5: 0.36363333 | BH5: 0 | BI5: 0 | BJ5: 2 | BK5: 2 | BL5: 2 | BM5: 2 | BN5: 0 | BO5: 0 | BP5: 0 | BQ5: 0 | BR5: 0 | BS5: 0 | BT5: 0 | BU5: 0 | BV5: 145.45333 | BW5: 0 | BX5: 0 | BY5: 0 | BZ5: 0 | CA5: TELEVENDAS | CB5: Marujinho | CC5: Vendedor/Marujinho | CD5: -3728651 | CE5: -38646193 | CF5: 2 | CG5: 2 - Meses | CH5: 1 - PÉSSIMO | CI5: 1 - < 300
A6: M_Capital | B6: 1441 | C6: Francineudo | D6: 1013 | G6: CLIENTES | H6: C00143 | I6: MERCADINHO PAULO E RISALVA | J6: PAULO SERGIO DE ALMEIDA ME | K6: 15 | M6: 7 | N6: PEQUENO VAREJO | O6: C | P6: Y | Q6: Horizonte | R6: Horizonte | S6: CE | T6: BR | U6: 45688 | X6: Sex | Y6: Semanal | AA6: Revenda | AB6: 21 dias | AC6: BLT-SOF | AD6: INTERIOR CE | AE6: 62880-000 | AF6: -4.0975048 | AG6: -38.4913877 | AH6: Sim | AI6: Não | AJ6: Não | AK6: 950.15 | AL6: 1000 | AM6: 0 | AN6: 0 | AO6: 0 | AP6: 0 | AQ6: 0 | AR6: 0 | AS6: 0 | AT6: 0 | AU6: 0 | AV6: 0 | AW6: 0 | AX6: 1 | AY6: 1 | AZ6: 1 | BA6: 1 | BV6: 0 | BW6: 0 | BX6: 0 | BY6: 0 | BZ6: 0 | CA6: CE | CB6: Varejo | CC6: Vendedor/Varejo | CD6: -40975048 | CE6: -38491387 | CF6: 3 | CG6: 3 - Meses | CH6: 0 - S/COMPRA | CI6: 0 - <= 0
A7: F_Sobral | B7: 2465 | C7: Bruno | D7: 1004 | G7: CLIENTES | H7: C00262 | I7: DISTAK LANCHES | J7: JOSE OSMAR DE OLIVEIRA | K7: 24 | M7: 7 | N7: PEQUENO VAREJO | O7: C | P7: Y | Q7: ACARAU | R7: ACARAÚ | S7: CE | T7: BR | U7: 45688 | X7: Seg | Y7: Q1 | AA7: Revenda | AB7: 13 dias | AC7: BLT-SOF | AD7: CAPITAL CE | AE7: 62580-000 | AF7: -2.885395 | AG7: -40.117661 | AH7: Sim | AI7: Não | AJ7: Não | AK7: 0 | AL7: 500 | AM7: 1 | AN7: 0 | AO7: 1 | AP7: 436.8 | AQ7: 607.32 | AR7: 0 | AS7: 0 | AT7: 1 | AU7: 1 | AV7: 0 | AW7: 0 | AX7: 1 | AY7: 1 | AZ7: 1 | BA7: 1 | BB7: 600 | BC7: 600 | BD7: 600 | BE7: 600 | BF7: 0.728 | BG7: 1.0122 | BH7: 0 | BI7: 0 | BJ7: 1 | BK7: 1 | BL7: 1 | BM7: 1 | BN7: 0 | BO7: 1 | BP7: 0 | BQ7: 0 | BR7: 0 | BS7: 1 | BT7: 0 | BU7: 0 | BV7: 348.04 | BW7: 0 | BX7: 0 | BY7: 0 | BZ7: 0 | CA7: CE | CB7: Varejo | CC7: Vendedor/Varejo | CD7: -2885395 | CE7: -40117661 | CF7: 2 | CG7: 2 - Meses | CH7: 2 - RUIM | CI7: 2 - < 600
A8: F_Sobral | B8: 2465 | C8: Adriano | D8: 993 | G8: CLIENTES | H8: C00264 | I8: L D I LANCHES | J8: FRANCISCO DARIO CAVALCANTE ME | K8: 24 | M8: 7 | N8: PEQUENO VAREJO | O8: C | P8: Y | Q8: CENTRO | R8: ITAPIPOCA | S8: CE | T8: BR | U8: 45688 | X8: Ter | Y8: Q1 | AA8: Revenda | AB8: 13 dias | AC8: BLT-SOF | AD8: VAREJO - SOBRAL | AE8: 62500-061 | AF8: -3.5009615 | AG8: -39.5836111 | AH8: Sim | AI8: Não | AJ8: Não | AK8: 0 | AL8: 500 | AM8: 0 | AN8: 0 | AO8: 0 | AP8: 0 | AQ8: 304.59 | AR8: 0 | AS8: 0 | AT8: 0 | AU8: 1 | AV8: 0 | AW8: 0 | AX8: 1 | AY8: 1 | AZ8: 1 | BA8: 1 | BV8: 101.53 | BW8: 0 | BX8: 0 | BY8: 0 | BZ8: 0 | CA8: CE | CB8: Varejo | CC8: Vendedor/Varejo | CD8: -35009615 | CE8: -39583611 | CF8: 2 | CG8: 2 - Meses | CH8: 1 - PÉSSIMO | CI8: 1 - < 300
A9: F_Sobral | B9: 2465 | C9: Gonzarlen | D9: 995 | G9: CLIENTES | H9: C00346 | I9: POSTO NORONHA (BR 020) | J9: NORONHA DIST DE PETROLEO LTDA | K9: 13 | M9: 7 | N9: PEQUENO VAREJO | O9: C | P9: Y | Q9: Campos Belos | R9: Caridade | S9: CE | T9: BR | U9: 45688 | X9: Seg | Y9: Q2 | AA9: Revenda | AB9: 21 dias | AC9: BLT-SANT 804-1 | AD9: INTERIOR CE | AE9: 62730-000 | AF9: -4.3692851 | AG9: -39.3206587 | AH9: Sim | AI9: Não | AJ9: Não | AK9: 0 | AL9: 1604 | AM9: 2 | AN9: 0 | AO9: 2 | AP9: 637 | AQ9: 0 | AR9: 0 | AS9: 0 | AT9: 1 | AU9: 0 | AV9: 0 | AW9: 0 | AX9: 1 | AY9: 1 | AZ9: 1 | BA9: 1 | BB9: 1200 | BC9: 1200 | BD9: 1200 | BE9: 1200 | BF9: 0.53083333 | BG9: 0 | BH9: 0 | BI9: 0 | BJ9: 2 | BK9: 2 | BL9: 2 | BM9: 2 | BN9: 0 | BO9: 0 | BP9: 0 | BQ9: 0 | BR9: 0 | BS9: 0 | BT9: 0 | BU9: 0 | BV9: 212.33333 | BW9: 0 | BX9: 0 | BY9: 0 | BZ9: 0 | CA9: CE | CB9: Varejo | CC9: Vendedor/Varejo | CD9: -43692851 | CE9: -39320658 | CF9: 3 | CG9: 3 - Meses | CH9: 1 - PÉSSIMO | CI9: 1 - < 300
A10: M_Nacionais | B10: 12 | C10: Lettelie | D10: 996 | G10: CLIENTES | H10: C00375 | I10: SUPER PONTO DA ECONOMIA | J10: PONTO DA ECONOMIA COMERCIAL DE ALIMENTOS LTDA - ME | K10: 1 | M10: 1 | N10: AUTOSSERVIÇO REGIONAL | O10: C | P10: Y | Q10: AEROLANDIA | R10: FORTALEZA | S10: CE | T10: BR | U10: 45691 | X10: Seg | Y10: Semanal | AA10: Revenda | AB10: 21 dias | AC10: BLT-SOF | AD10: AUTOSSERVIÇO CE | AE10: 60851-290 | AF10: -3.777306 | AG10: -38.513074 | AH10: Sim | AI10: Não | AJ10: Não | AK10: 0 | AL10: 1500 | AM10: 0 | AN10: 0 | AO10: 0 | AP10: 0 | AQ10: 0 | AR10: 0 | AS10: 0 | AT10: 0 | AU10: 0 | AV10: 0 | AW10: 0 | AX10: 1 | AY10: 1 | AZ10: 1 | BA10: 1 | BV10: 0 | BW10: 0 | BX10: 0 | BY10: 0 | BZ10: 0 | CA10: CE | CB10: AS | CC10: Vendedor/AS | CD10: -3777306 | CE10: -38513074 | CF10: 3 | CG10: 3 - Meses | CH10: 0 - S/COMPRA | CI10: 0 - <= 0
A11: M_Capital | B11: 1441 | C11: Leonardo | D11: 1007 | G11: CLIENTES | H11: C00423 | I11: CHURRASCARIA FERNANDES | J11: ALDENIRA DUARTE DE OLIVEIRA | K11: 31 | M11: 10 | N11: INATIVO | O11: C | P11: Y | Q11: BARRA DO CEARA | R11: FORTALEZA | S11: CE | T11: BR | U11: 45691 | X11: Qui | Y11: Semanal | AA11: Revenda | AB11: 5 dias | AC11: DINHEIRO$ | AD11: LOJA - CEARÁ - ATACADO | AE11: 60332-360 | AF11: -3.700796 | AG11: -38.578752 | AH11: Sim | AI11: Não | AJ11: Não | AK11: 0 | AL11: 0 | AM11: 0 | AN11: 0 | AO11: 0 | AP11: 0 | AQ11: 0 | AR11: 0 | AS11: 0 | AT11: 0 | AU11: 0 | AV11: 0 | AW11: 0 | AX11: 1 | AY11: 1 | AZ11: 1 | BA11: 1 | BV11: 0 | BW11: 0 | BX11: 0 | BY11: 0 | BZ11: 0 | CA11: CE | CB11: Varejo | CC11: Vendedor/Varejo | CF11: 3 | CG11: 3 - Meses | CH11: 0 - S/COMPRA | CI11: 0 - <= 0
A12: M_Capital | B12: 1441 | C12: Roberto | D12: 1018 | G12: CLIENTES | H12: C00475 | I12: PONTO DO LANCHE (JARD FLUMINENSE) | J12: DOURA NASCIMENTO DE ALMEIDA | K12: 24 | M12: 7 | N12: PEQUENO VAREJO | O12: C | P12: Y | Q12: JARDIM FLUMINENSE | R12: FORTALEZA | S12: CE | T12: BR | U12: 45688 | X12: Sex | Y12: Q2 | AA12: Revenda | AB12: 10 dias | AC12: BLT-SANT 804-1 | AD12: CAPITAL CE | AE12: 60734-100 | AF12: -3.815073 | AG12: -38.603461 | AH12: Sim | AI12: Não | AJ12: Não | AK12: 0 | AL12: 800 | AM12: 1 | AN12: 0 | AO12: 1 | AP12: 0 | AQ12: 0 | AR12: 0 | AS12: 0 | AT12: 0 | AU12: 0 | AV12: 0 | AW12: 0 | AX12: 1 | AY12: 1 | AZ12: 1 | BA12: 1 | BB12: 600 | BC12: 600 | BD12: 600 | BE12: 600 | BF12: 0 | BG12: 0 | BH12: 0 | BI12: 0 | BJ12: 1 | BK12: 1 | BL12: 1 | BM12: 1 | BN12: 0 | BO12: 0 | BP12: 0 | BQ12: 0 | BR12: 0 | BS12: 0 | BT12: 0 | BU12: 0 | BV12: 0 | BW12: 0 | BX12: 0 | BY12: 0 | BZ12: 0 | CA12: CE | CB12: Varejo | CC12: Vendedor/Varejo | CD12: -3815073 | CE12: -38603461 | CF12: 3 | CG12: 3 - Meses | CH12: 0 - S/COMPRA | CI12: 0 - <= 0
A13: M_Capital | B13: 1441 | C13: Roberto | D13: 1018 | G13: CLIENTES | H13: C00484 | I13: CHURRASCARIA E PIZZARIA RECANTO DA PICANHA | J13: ANTONIA LUCIA DA COSTA SOUSA | K13: 31 | M13: 10 | N13: INATIVO | O13: C | P13: Y | Q13: ACARACUZINHO | R13: Maracanaú | S13: CE | T13: BR | U13: 45688 | X13: Sex | Y13: Q1 | AA13: Revenda | AB13: 5 dias | AC13: BLT-ITAÚ 130681 | AD13: CAPITAL CE | AE13: 61936-110 | AF13: -3.8484055 | AG13: -38.6168176 | AH13: Sim | AI13: Não | AJ13: Sim | AK13: 0 | AL13: 1200 | AM13: 0 | AN13: 0 | AO13: 0 | AP13: 0 | AQ13: 0 | AR13: 0 | AS13: 0 | AT13: 0 | AU13: 0 | AV13: 0 | AW13: 0 | AX13: 1 | AY13: 1 | AZ13: 1 | BA13: 1 | BV13: 0 | BW13: 0 | BX13: 0 | BY13: 0 | BZ13: 0 | CA13: CE | CB13: Varejo | CC13: Vendedor/Varejo | CD13: -38484055 | CE13: -38616817 | CF13: 3 | CG13: 3 - Meses | CH13: 0 - S/COMPRA | CI13: 0 - <= 0
A14: M_Capital | B14: 1441 | C14: Alexsanderson | D14: 1061 | G14: CLIENTES | H14: C00486 | I14: MERCADINHO ABENCOADO 2 | J14: PEDRO ACASIO DE SOUSA FILHO ME | K14: 15 | M14: 7 | N14: PEQUENO VAREJO | O14: C | P14: Y | Q14: MOURA BRASIL(JACARECANGA) | R14: FORTALEZA | S14: CE | T14: BR | U14: 45691 | X14: Ter | Y14: Q1 | AA14: Revenda | AB14: 5 dias | AC14: BLT-ITAÚ 130681 | AD14: CAPITAL CE | AE14: 60010-200 | AF14: -3.7198133 | AG14: -38.5336972 | AH14: Sim | AI14: Não | AJ14: Sim | AK14: 797.27 | AL14: 880 | AM14: 0 | AN14: 0 | AO14: 0 | AP14: 0 | AQ14: 0 | AR14: 0 | AS14: 0 | AT14: 0 | AU14: 0 | AV14: 0 | AW14: 0 | AX14: 1 | AY14: 1 | AZ14: 1 | BA14: 1 | BV14: 0 | BW14: 0 | BX14: 0 | BY14: 0 | BZ14: 0 | CA14: CE | CB14: Varejo | CC14: Vendedor/Varejo | CD14: -37198133 | CE14: -38533697 | CF14: 3 | CG14: 3 - Meses | CH14: 0 - S/COMPRA | CI14: 0 - <= 0
A15: M_Nacionais | B15: 12 | C15: Nacionais Cap | D15: 998 | G15: G BARBOSA | H15: C00541 | I15: G BARBOSA (W SOARES) | J15: CENCOSUD BRASIL COM LTDA | K15: 2 | M15: 2 | N15: AUTOSSERVIÇO NACIONAL | O15: C | P15: Y | Q15: Edson Queiroz | R15: Fortaleza | S15: CE | T15: BR | U15: 45688 | X15: Seg | Y15: Semanal | AA15: Revenda | AB15: 45 dias | AC15: DEPOSITO | AD15: AUTOSSERVIÇO CE | AE15: 60811-341 | AF15: -3.773404 | AG15: -38.48167 | AH15: Não | AI15: Não | AJ15: Não | AK15: 3482.82 | AL15: 20000 | AM15: 2 | AN15: 1 | AO15: 3 | AP15: 0 | AQ15: 3119.85 | AR15: 0 | AS15: 0 | AT15: 0 | AU15: 1 | AV15: 0 | AW15: 0 | AX15: 1 | AY15: 1 | AZ15: 1 | BA15: 1 | BB15: 1800 | BC15: 1800 | BD15: 1800 | BE15: 1800 | BF15: 0 | BG15: 1.73325 | BH15: 0 | BI15: 0 | BJ15: 3 | BK15: 3 | BL15: 3 | BM15: 3 | BN15: 0 | BO15: 3 | BP15: 0 | BQ15: 0 | BR15: 0 | BS15: 1 | BT15: 0 | BU15: 0 | BV15: 1039.95 | BW15: 1 | BX15: 0 | BY15: 1 | BZ15: 1 | CA15: CE | CB15: AS | CC15: Promotor | CD15: -3773404 | CE15: -3848167 | CF15: 2 | CG15: 2 - Meses | CH15: 4 - BOM | CI15: 4 - < 3000
A16: M_Capital | B16: 1441 | C16: Leonardo | D16: 1007 | G16: CLIENTES | H16: C00579 | I16: MERCADINHO O LOURO (BELA VISTA) | J16: F V DE AMORIM ME | K16: 15 | M16: 7 | N16: PEQUENO VAREJO | O16: C | P16: Y | Q16: BELA VISTA | R16: FORTALEZA | S16: CE | T16: BR | U16: 45688 | X16: Sex | Y16: Q1 | AA16: Revenda | AB16: 14 dias | AC16: BLT-SOF | AD16: CAPITAL CE | AE16: 60441-385 | AF16: -3.7510683 | AG16: -38.5630467 | AH16: Sim | AI16: Não | AJ16: Não | AK16: 0 | AL16: 700 | AM16: 0 | AN16: 0 | AO16: 0 | AP16: 0 | AQ16: 0 | AR16: 0 | AS16: 0 | AT16: 0 | AU16: 0 | AV16: 0 | AW16: 0 | AX16: 1 | AY16: 1 | AZ16: 1 | BA16: 1 | BV16: 0 | BW16: 0 | BX16: 0 | BY16: 0 | BZ16: 0 | CA16: CE | CB16: Varejo | CC16: Vendedor/Varejo | CD16: -37510683 | CE16: -38563046 | CF16: 3 | CG16: 3 - Meses | CH16: 0 - S/COMPRA | CI16: 0 - <= 0
A17: F_Sobral | B17: 2465 | C17: Adriano | D17: 993 | G17: CLIENTES | H17: C00611 | I17: MERCANTIL GERRY | J17: GERRY ADRIANY DE SOUSA ME | K17: 15 | M17: 7 | N17: PEQUENO VAREJO | O17: C | P17: Y | Q17: SAO SEBASTIAO | R17: ITAPIPOCA | S17: CE | T17: BR | U17: 45688 | X17: Ter | Y17: Semanal | AA17: Revenda | AB17: 15 dias | AC17: BLT-SOF | AD17: INTERIOR CE | AE17: 62508-190 | AF17: -3.503178 | AG17: -39.5802923 | AH17: Sim | AI17: Não | AJ17: Não | AK17: 555.14 | AL17: 0 | AM17: 0 | AN17: 0 | AO17: 0 | AP17: 0 | AQ17: 0 | AR17: 0 | AS17: 0 | AT17: 0 | AU17: 0 | AV17: 0 | AW17: 0 | AX17: 1 | AY17: 1 | AZ17: 1 | BA17: 1 | BV17: 0 | BW17: 0 | BX17: 0 | BY17: 0 | BZ17: 0 | CA17: CE | CB17: Varejo | CC17: Vendedor/Varejo | CD17: -3503178 | CE17: -39580292 | CF17: 3 | CG17: 3 - Meses | CH17: 0 - S/COMPRA | CI17: 0 - <= 0
A18: M_Capital | B18: 1441 | C18: Alexsanderson | D18: 1061 | G18: CLIENTES | H18: C00617 | I18: REVISTARIA JOIA (CENTRO) | J18: JOSE EDMAR CORREIA | K18: 10 | M18: 7 | N18: PEQUENO VAREJO | O18: C | P18: Y | Q18: CENTRO | R18: FORTALEZA | S18: CE | T18: BR | U18: 45691 | X18: Seg | Y18: Q1 | AA18: Revenda | AB18: 13 dias | AC18: BLT-ITAÚ 130681 | AD18: CAPITAL CE | AE18: 60020-030 | AF18: -3.7326888 | AG18: -38.532397 | AH18: Sim | AI18: Não | AJ18: Sim | AK18: 628.22 | AL18: 1200 | AM18: 0 | AN18: 0 | AO18: 0 | AP18: 0 | AQ18: 0 | AR18: 0 | AS18: 0 | AT18: 0 | AU18: 0 | AV18: 0 | AW18: 0 | AX18: 1 | AY18: 1 | AZ18: 1 | BA18: 1 | BV18: 0 | BW18: 0 | BX18: 0 | BY18: 0 | BZ18: 0 | CA18: CE | CB18: Varejo | CC18: Vendedor/Varejo | CD18: -37326888 | CE18: -38532397 | CF18: 3 | CG18: 3 - Meses | CH18: 0 - S/COMPRA | CI18: 0 - <= 0
A19: F_Sobral | B19: 2465 | C19: Gonzarlen | D19: 995 | G19: CLIENTES | H19: C00635 | I19: CHURRASCARIA O CHICO | J19: FRANCISCO ANTONIO RODRIGUES MOREIRA | K19: 22 | M19: 7 | N19: PEQUENO VAREJO | O19: C | P19: Y | Q19: Arruda | R19: Paramoti | S19: CE | T19: BR | U19: 45688 | X19: Qui | Y19: Q1 | AA19: Revenda | AB19: 15 dias | AC19: SMARTCOB | AD19: CAPITAL CE | AE19: 62736-000 | AF19: -4.097849 | AG19: -39.239166 | AH19: Sim | AI19: Não | AJ19: Não | AK19: 1015.42 | AL19: 500 | AM19: 0 | AN19: 0 | AO19: 0 | AP19: 0 | AQ19: 0 | AR19: 0 | AS19: 0 | AT19: 0 | AU19: 0 | AV19: 0 | AW19: 0 | AX19: 1 | AY19: 1 | AZ19: 1 | BA19: 1 | BV19: 0 | BW19: 0 | BX19: 0 | BY19: 0 | BZ19: 0 | CA19: CE | CB19: Varejo | CC19: Vendedor/Varejo | CD19: -4097849 | CE19: -39239166 | CF19: 3 | CG19: 3 - Meses | CH19: 0 - S/COMPRA | CI19: 0 - <= 0
A20: M_Regionais | B20: 707 | C20: Benzelieu | D20: 1000 | G20: UNIFORCA I | H20: C00636 | I20: ISMAEL SUPERMERCADO I | J20: ISMAEL SUPERMERCADO LTDA EPP | K20: 31 | M20: 10 | N20: INATIVO | O20: C | P20: Y | Q20: LAGOA REDONDA | R20: FORTALEZA | S20: CE | T20: BR | U20: 45688 | X20: Ter | Y20: Semanal | Z20: 3 | AA20: Revenda | AB20: 21 dias | AC20: BLT-SANT 804-1 | AD20: AUTOSSERVIÇO CE | AE20: 60831-370 | AF20: -3.8264719 | AG20: -38.4742945 | AH20: Sim | AI20: Não | AJ20: Não | AK20: 0 | AL20: 1500 | AM20: 0 | AN20: 0 | AO20: 0 | AP20: 0 | AQ20: 0 | AR20: 0 | AS20: 0 | AT20: 0 | AU20: 0 | AV20: 0 | AW20: 0 | AX20: 1 | AY20: 1 | AZ20: 1 | BA20: 1 | BV20: 0 | BW20: 0 | BX20: 0 | BY20: 0 | BZ20: 0 | CA20: CE | CB20: AS | CC20: Vendedor/AS | CD20: -38264719 | CE20: -38474294 | CF20: 3 | CG20: 3 - Meses | CH20: 0 - S/COMPRA | CI20: 0 - <= 0
A21: M_Regionais | B21: 707 | C21: Benzelieu | D21: 1000 | G21: UNIFORCA I | H21: C00637 | I21: ISMAEL SUPERMERCADO II | J21: ISMAEL SUPERMERCADO LTDA | K21: 1 | M21: 1 | N21: AUTOSSERVIÇO REGIONAL | O21: C | P21: Y | Q21: ANCURI | R21: Fortaleza | S21: CE | T21: BR | U21: 45688 | X21: Qui | Y21: Semanal | Z21: 3 | AA21: Revenda | AB21: 21 dias | AC21: BLT-ITAÚ 130681 | AD21: AUTOSSERVIÇO CE | AE21: 60973-195 | AF21: -3.85762 | AG21: -38.5023 | AH21: Sim | AI21: Não | AJ21: Não | AK21: 0 | AL21: 2000 | AM21: 0 | AN21: 0 | AO21: 0 | AP21: 0 | AQ21: 0 | AR21: 0 | AS21: 0 | AT21: 0 | AU21: 0 | AV21: 0 | AW21: 0 | AX21: 1 | AY21: 1 | AZ21: 1 | BA21: 1 | BV21: 0 | BW21: 0 | BX21: 0 | BY21: 0 | BZ21: 0 | CA21: CE | CB21: AS | CC21: Vendedor/AS | CD21: -385762 | CE21: -385023 | CF21: 3 | CG21: 3 - Meses | CH21: 0 - S/COMPRA | CI21: 0 - <= 0
A22: F_Sobral | B22: 2465 | C22: Gonzarlen | D22: 995 | G22: CLIENTES | H22: C00659 | I22: FARMA SERTAO CENTRAL | J22: PEDROSA E ALVES LTDA ME | K22: 11 | M22: 7 | N22: PEQUENO VAREJO | O22: C | P22: Y | Q22: Centro | R22: Itatira | S22: CE | T22: BR | U22: 45688 | X22: Ter | Y22: Q1 | AA22: Revenda | AB22: 21 dias | AC22: BLT-ITAÚ 130681 | AD22: INTERIOR CE | AE22: 62620-000 | AF22: -4.526461 | AG22: -39.62051 | AH22: Sim | AI22: Não | AJ22: Sim | AK22: 0 | AL22: 700 | AM22: 0 | AN22: 0 | AO22: 0 | AP22: 0 | AQ22: 0 | AR22: 0 | AS22: 0 | AT22: 0 | AU22: 0 | AV22: 0 | AW22: 0 | AX22: 1 | AY22: 1 | AZ22: 1 | BA22: 1 | BV22: 0 | BW22: 0 | BX22: 0 | BY22: 0 | BZ22: 0 | CA22: CE | CB22: Varejo | CC22: Vendedor/Varejo | CD22: -4526461 | CE22: -3962051 | CF22: 3 | CG22: 3 - Meses | CH22: 0 - S/COMPRA | CI22: 0 - <= 0
A23: M_Capital | B23: 1441 | C23: Felipe | D23: 1010 | G23: CLIENTES | H23: C00660 | I23: MERCADINHO POPIA | J23: LUIZ ANTONIO F VIANA | K23: 15 | M23: 7 | N23: PEQUENO VAREJO | O23: C | P23: Y | Q23: ANTONIO MIGUEL | R23: ITAITINGA | S23: CE | T23: BR | U23: 45688 | X23: Seg | Y23: Q1 | AA23: Revenda | AB23: 10 dias | AC23: BLT-SOF | AD23: CAPITAL CE | AE23: 61880-000 | AF23: -3.9752598 | AG23: -38.5170933 | AH23: Sim | AI23: Não | AJ23: Não | AK23: 731.49 | AL23: 250 | AM23: 0 | AN23: 0 | AO23: 0 | AP23: 0 | AQ23: 0 | AR23: 0 | AS23: 0 | AT23: 0 | AU23: 0 | AV23: 0 | AW23: 0 | AX23: 1 | AY23: 1 | AZ23: 1 | BA23: 1 | BV23: 0 | BW23: 0 | BX23: 0 | BY23: 0 | BZ23: 0 | CA23: CE | CB23: Varejo | CC23: Vendedor/Varejo | CD23: -39752598 | CE23: -38517093 | CF23: 3 | CG23: 3 - Meses | CH23: 0 - S/COMPRA | CI23: 0 - <= 0
A24: M_Capital | B24: 1441 | C24: Caio | D24: 1008 | G24: CLIENTES | H24: C00702 | I24: CHURRASCARIA E PIZZARIA SAO FRANCISCO | J24: FRANCISCO FERREIRA M LANCHONETE ME | K24: 22 | M24: 7 | N24: PEQUENO VAREJO | O24: C | P24: Y | Q24: Icaraí | R24: Caucaia | S24: CE | T24: BR | U24: 45691 | X24: Qua | Y24: Q2 | AA24: Revenda | AB24: avista | AC24: BLT-SOF | AD24: CAPITAL CE | AE24: 61620-340 | AF24: -3.6757542 | AG24: -38.6671365 | AH24: Sim | AI24: Não | AJ24: Sim | AK24: 4731.56 | AL24: 0 | AM24: 1 | AN24: 0 | AO24: 1 | AP24: 1456.66 | AQ24: 0 | AR24: 0 | AS24: 0 | AT24: 1 | AU24: 0 | AV24: 0 | AW24: 0 | AX24: 1 | AY24: 1 | AZ24: 1 | BA24: 1 | BB24: 600 | BC24: 600 | BD24: 600 | BE24: 600 | BF24: 2.4277667 | BG24: 0 | BH24: 0 | BI24: 0 | BJ24: 1 | BK24: 1 | BL24: 1 | BM24: 1 | BN24: 1 | BO24: 0 | BP24: 0 | BQ24: 0 | BR24: 1 | BS24: 0 | BT24: 0 | BU24: 0 | BV24: 485.55333 | BW24: 0 | BX24: 0 | BY24: 0 | BZ24: 0 | CA24: CE | CB24: Varejo | CC24: Vendedor/Varejo | CD24: -36757542 | CE24: -38667136 | CF24: 3 | CG24: 3 - Meses | CH24: 2 - RUIM | CI24: 2 - < 600
A25: M_Nacionais | B25: 12 | C25: Franklin | D25: 1005 | G25: CLIENTES AS | H25: C00711 | I25: MERCADINHO O IRMAO (MARANGUAPE) | J25: COMERCIO VAREJISTA DE ALIMENTOS O IRMAO LTDA | K25: 31 | M25: 10 | N25: INATIVO | O25: C | P25: Y | Q25: CENTRO | R25: MARANGUAPE | S25: CE | T25: BR | U25: 45688 | X25: Ter | Y25: Semanal | AA25: Revenda | AB25: 15 dias | AC25: BLT-ITAÚ 130681 | AD25: AUTOSSERVIÇO CE | AE25: 61940-160 | AF25: -3.8918126 | AG25: -38.683258 | AH25: Sim | AI25: Não | AJ25: Não | AK25: 0 | AL25: 660 | AM25: 0 | AN25: 0 | AO25: 0 | AP25: 0 | AQ25: 0 | AR25: 0 | AS25: 0 | AT25: 0 | AU25: 0 | AV25: 0 | AW25: 0 | AX25: 1 | AY25: 1 | AZ25: 1 | BA25: 1 | BV25: 0 | BW25: 0 | BX25: 0 | BY25: 0 | BZ25: 0 | CA25: CE | CB25: AS | CC25: Vendedor/AS | CD25: -38918126 | CE25: -38683258 | CF25: 3 | CG25: 3 - Meses | CH25: 0 - S/COMPRA | CI25: 0 - <= 0
A26: M_Capital | B26: 1441 | C26: Leonardo | D26: 1007 | G26: CLIENTES | H26: C00739 | I26: PIZZARIA E PASTELARIA MAMAMIA | J26: OZANIRA MENDONCA PARENTE | K26: 24 | M26: 7 | N26: PEQUENO VAREJO | O26: C | P26: Y | Q26: JOAO XXIII | R26: FORTALEZA | S26: CE | T26: BR | U26: 45688 | X26: Sex | Y26: Q1 | AA26: Revenda | AB26: 5 dias | AC26: BLT-ITAÚ 130681 | AD26: CAPITAL CE | AE26: 60525-581 | AF26: -3.7746378 | AG26: -38.5806175 | AH26: Sim | AI26: Não | AJ26: Sim | AK26: 484.88 | AL26: 800 | AM26: 0 | AN26: 0 | AO26: 0 | AP26: 0 | AQ26: 0 | AR26: 0 | AS26: 0 | AT26: 0 | AU26: 0 | AV26: 0 | AW26: 0 | AX26: 1 | AY26: 1 | AZ26: 1 | BA26: 1 | BV26: 0 | BW26: 0 | BX26: 0 | BY26: 0 | BZ26: 0 | CA26: CE | CB26: Varejo | CC26: Vendedor/Varejo | CD26: -37746378 | CE26: -38580617 | CF26: 3 | CG26: 3 - Meses | CH26: 0 - S/COMPRA | CI26: 0 - <= 0
A27: M_Nacionais | B27: 12 | C27: Franklin | D27: 1005 | G27: MAXI REDE | H27: C00749 | I27: SUPERMERCADO CANADA | J27: SUPERMERCADO CANADA LTDA ME | K27: 1 | M27: 1 | N27: AUTOSSERVIÇO REGIONAL | O27: C | P27: Y | Q27: GRANJA PORTUGAL | R27: FORTALEZA | S27: CE | T27: BR | U27: 45688 | X27: Sex | Y27: Semanal | Z27: 5 | AA27: Revenda | AB27: 35 dias | AC27: BLT-SOF | AD27: AUTOSSERVIÇO CE | AE27: 60541-495 | AF27: -3.7779164 | AG27: -38.597836 | AH27: Não | AI27: Não | AJ27: Não | AK27: 0 | AL27: 20000 | AM27: 0 | AN27: 0 | AO27: 0 | AP27: 0 | AQ27: 0 | AR27: 0 | AS27: 0 | AT27: 0 | AU27: 0 | AV27: 0 | AW27: 0 | AX27: 1 | AY27: 1 | AZ27: 1 | BA27: 1 | BV27: 0 | BW27: 0 | BX27: 0 | BY27: 0 | BZ27: 0 | CA27: CE | CB27: AS | CC27: Vendedor/AS | CD27: -37779164 | CE27: -38597836 | CF27: 3 | CG27: 3 - Meses | CH27: 0 - S/COMPRA | CI27: 0 - <= 0
A28: F_Sobral | B28: 2465 | C28: Gonzarlen | D28: 995 | G28: CLIENTES | H28: C00779 | I28: CENTRAL FARMA | J28: FRANCISCO AMILTON L BRITO ME | K28: 11 | M28: 7 | N28: PEQUENO VAREJO | O28: C | P28: Y | Q28: Centro | R28: Madalena | S28: CE | T28: BR | U28: 45688 | X28: Ter | Y28: Q1 | AA28: Revenda | AB28: 21 dias | AC28: BLT-SOF | AD28: INTERIOR CE | AE28: 63860-000 | AF28: -4.8527784 | AG28: -39.5756628 | AH28: Sim | AI28: Não | AJ28: Não | AK28: -1483.78 | AL28: 852 | AM28: 1 | AN28: 0 | AO28: 1 | AP28: 393.08 | AQ28: 1274.68 | AR28: 76 | AS28: 0 | AT28: 1 | AU28: 1 | AV28: 0 | AW28: 0 | AX28: 1 | AY28: 1 | AZ28: 1 | BA28: 1 | BB28: 600 | BC28: 600 | BD28: 600 | BE28: 600 | BF28: 0.65513333 | BG28: 2.1244667 | BH28: 0.12666667 | BI28: 0 | BJ28: 1 | BK28: 1 | BL28: 1 | BM28: 1 | BN28: 0 | BO28: 1 | BP28: 0 | BQ28: 0 | BR28: 0 | BS28: 1 | BT28: 0 | BU28: 0 | BV28: 581.25333 | BW28: 0 | BX28: 0 | BY28: 0 | BZ28: 0 | CA28: CE | CB28: Varejo | CC28: Vendedor/Varejo | CD28: -48527784 | CE28: -39575662 | CF28: 2 | CG28: 2 - Meses | CH28: 2 - RUIM | CI28: 2 - < 600
A29: M_Capital | B29: 1441 | C29: Alexsanderson | D29: 1061 | G29: CLIENTES | H29: C00823 | I29: MERCADINHO RITIMEL | J29: F R S SILVA EPP | K29: 15 | M29: 7 | N29: PEQUENO VAREJO | O29: C | P29: Y | Q29: CAIS DO PORTO | R29: FORTALEZA | S29: CE | T29: BR | U29: 45688 | X29: Sab | Y29: Q2 | AA29: Revenda | AB29: 10 dias | AC29: SMARTCOB | AD29: CAPITAL CE | AE29: 60180-140 | AF29: -3.7137233 | AG29: -38.4651228 | AH29: Sim | AI29: Não | AJ29: Não | AK29: 0 | AL29: 1750 | AM29: 0 | AN29: 0 | AO29: 0 | AP29: 0 | AQ29: 0 | AR29: 0 | AS29: 0 | AT29: 0 | AU29: 0 | AV29: 0 | AW29: 0 | AX29: 1 | AY29: 1 | AZ29: 1 | BA29: 1 | BV29: 0 | BW29: 0 | BX29: 0 | BY29: 0 | BZ29: 0 | CA29: CE | CB29: Varejo | CC29: Vendedor/Varejo | CD29: -37137233 | CE29: -38465122 | CF29: 3 | CG29: 3 - Meses | CH29: 0 - S/COMPRA | CI29: 0 - <= 0
A30: F_Sobral | B30: 2465 | C30: Bruno | D30: 1004 | G30: CLIENTES | H30: C00833 | I30: MERCADINHO CASA BRANCA (ITAREMA) | J30: FRANCISCO FRANCINE DE SANTANA | K30: 15 | M30: 7 | N30: PEQUENO VAREJO | O30: C | P30: Y | Q30: ITAREMA | R30: ITAREMA | S30: CE | T30: BR | U30: 45688 | X30: Ter | Y30: Q1 | AA30: Revenda | AB30: 10 dias | AC30: BLT-SOF | AD30: INTERIOR CE | AE30: 62590-000 | AF30: -2.9203301 | AG30: -39.9204283 | AH30: Sim | AI30: Não | AJ30: Não | AK30: 0 | AL30: 800 | AM30: 0 | AN30: 0 | AO30: 0 | AP30: 0 | AQ30: 0 | AR30: 0 | AS30: 0 | AT30: 0 | AU30: 0 | AV30: 0 | AW30: 0 | AX30: 1 | AY30: 1 | AZ30: 1 | BA30: 1 | BV30: 0 | BW30: 0 | BX30: 0 | BY30: 0 | BZ30: 0 | CA30: CE | CB30: Varejo | CC30: Vendedor/Varejo | CD30: -29203301 | CE30: -39920428 | CF30: 3 | CG30: 3 - Meses | CH30: 0 - S/COMPRA | CI30: 0 - <= 0
A31: F_Mossoró | B31: 12 | C31: Melo Monteiro | D31: 1030 | G31: CLIENTES | H31: C00847 | I31: MERCADINHO FORTINHO DA BARRA | J31: LAZARO JUNIOR MEDEIROS DE MELO | K31: 15 | M31: 7 | N31: PEQUENO VAREJO | O31: C | P31: Y | Q31: Centro | R31: Fortim | S31: CE | T31: BR | U31: 45688 | X31: Ter | Y31: Q2 | AA31: Revenda | AB31: 13 dias | AC31: BLT-ITAÚ 130681 | AD31: CAPITAL CE | AE31: 62815-000 | AF31: -4.4326943 | AG31: -37.7821695 | AH31: Sim | AI31: Não | AJ31: Sim | AK31: 0 | AL31: 700 | AM31: 0 | AN31: 0 | AO31: 0 | AP31: 0 | AQ31: 0 | AR31: 0 | AS31: 0 | AT31: 0 | AU31: 0 | AV31: 0 | AW31: 0 | AX31: 1 | AY31: 1 | AZ31: 1 | BA31: 1 | BV31: 0 | BW31: 0 | BX31: 0 | BY31: 0 | BZ31: 0 | CA31: CE | CB31: AS | CC31: Vendedor/AS | CF31: 3 | CG31: 3 - Meses | CH31: 0 - S/COMPRA | CI31: 0 - <= 0
A32: F_Sobral | B32: 2465 | C32: Gonzarlen | D32: 995 | G32: CLIENTES | H32: C00856 | I32: MERCADINHO EDMAR (CAMPOS BELO) | J32: MERCADINHO EDMAR RUFINO LTDA | K32: 15 | M32: 7 | N32: PEQUENO VAREJO | O32: C | P32: Y | Q32: INHUPORANGA | R32: CARIDADE | S32: CE | T32: BR | U32: 45688 | X32: Sex | Y32: Q1 | AA32: Revenda | AB32: 13 dias | AC32: SMARTCOB | AD32: INTERIOR CE | AE32: 62730-000 | AF32: -4.097644 | AG32: -39.0539816 | AH32: Sim | AI32: Não | AJ32: Não | AK32: 0 | AL32: 800 | AM32: 0 | AN32: 0 | AO32: 0 | AP32: 0 | AQ32: 0 | AR32: 0 | AS32: 0 | AT32: 0 | AU32: 0 | AV32: 0 | AW32: 0 | AX32: 1 | AY32: 1 | AZ32: 1 | BA32: 1 | BV32: 0 | BW32: 0 | BX32: 0 | BY32: 0 | BZ32: 0 | CA32: CE | CB32: Varejo | CC32: Vendedor/Varejo | CD32: -4097644 | CE32: -39053981 | CF32: 3 | CG32: 3 - Meses | CH32: 0 - S/COMPRA | CI32: 0 - <= 0
A33: F_Sobral | B33: 2465 | C33: Gonzarlen | D33: 995 | G33: CLIENTES | H33: C00866 | I33: SUPERMERCADO FAMILIA | J33: SUPERMERCADO JG LTDA | K33: 1 | M33: 1 | N33: AUTOSSERVIÇO REGIONAL | O33: C | P33: Y | Q33: Centro | R33: REDENÇÃO | S33: CE | T33: BR | U33: 45688 | X33: Seg | Y33: Q1 | AA33: Revenda | AB33: 21 dias | AC33: SMARTCOB | AD33: INTERIOR CE | AE33: 62790-000 | AF33: -4.22256 | AG33: -38.730234 | AH33: Sim | AI33: Não | AJ33: Sim | AK33: 0 | AL33: 700 | AM33: 0 | AN33: 0 | AO33: 0 | AP33: 0 | AQ33: 0 | AR33: 0 | AS33: 0 | AT33: 0 | AU33: 0 | AV33: 0 | AW33: 0 | AX33: 1 | AY33: 1 | AZ33: 1 | BA33: 1 | BV33: 0 | BW33: 0 | BX33: 0 | BY33: 0 | BZ33: 0 | CA33: CE | CB33: Varejo | CC33: Vendedor/Varejo | CD33: -422256 | CE33: -38730234 | CF33: 3 | CG33: 3 - Meses | CH33: 0 - S/COMPRA | CI33: 0 - <= 0
A34: F_Mossoró | B34: 12 | C34: Melo Monteiro | D34: 1030 | G34: CLIENTES | H34: C00933 | I34: CHURASCARIA FRANGO DOURADO | J34: FRANCISCO GOMES S CHURRASCARIA ME | K34: 22 | M34: 7 | N34: PEQUENO VAREJO | O34: C | P34: Y | Q34: Centro | R34: Aracati | S34: CE | T34: BR | U34: 45688 | X34: Ter | Y34: Q2 | AA34: Revenda | AB34: 13 dias | AC34: SMARTCOB | AD34: INTERIOR CE | AE34: 62800-000 | AF34: -4.5659645 | AG34: -37.7716021 | AH34: Sim | AI34: Não | AJ34: Não | AK34: 688.97 | AL34: 5513 | AM34: 0 | AN34: 0 | AO34: 0 | AP34: 0 | AQ34: 0 | AR34: 0 | AS34: 0 | AT34: 0 | AU34: 0 | AV34: 0 | AW34: 0 | AX34: 1 | AY34: 1 | AZ34: 1 | BA34: 1 | BV34: 0 | BW34: 0 | BX34: 0 | BY34: 0 | BZ34: 0 | CA34: CE | CB34: AS | CC34: Vendedor/AS | CD34: -45659645 | CE34: -37771602 | CF34: 3 | CG34: 3 - Meses | CH34: 0 - S/COMPRA | CI34: 0 - <= 0
A35: F_Sobral | B35: 2465 | C35: Gonzarlen | D35: 995 | G35: CLIENTES | H35: C00973 | I35: MERCADINHO NOSSA SENHORA DE FATIMA | J35: M JAILZA BARROS ROBERTO ME MICROEMPRESA | K35: 15 | M35: 7 | N35: PEQUENO VAREJO | O35: C | P35: Y | Q35: Campos Belos | R35: Caridade | S35: CE | T35: BR | U35: 45688 | X35: Qui | Y35: Q1 | AA35: Revenda | AB35: 5 dias | AC35: BLT-SOF | AD35: INTERIOR CE | AE35: 62730-000 | AF35: -4.094675 | AG35: -39.056715 | AH35: Sim | AI35: Não | AJ35: Sim | AK35: 0 | AL35: 700 | AM35: 1 | AN35: 0 | AO35: 1 | AP35: 0 | AQ35: 0 | AR35: 0 | AS35: 0 | AT35: 0 | AU35: 0 | AV35: 0 | AW35: 0 | AX35: 1 | AY35: 1 | AZ35: 1 | BA35: 1 | BB35: 600 | BC35: 600 | BD35: 600 | BE35: 600 | BF35: 0 | BG35: 0 | BH35: 0 | BI35: 0 | BJ35: 1 | BK35: 1 | BL35: 1 | BM35: 1 | BN35: 0 | BO35: 0 | BP35: 0 | BQ35: 0 | BR35: 0 | BS35: 0 | BT35: 0 | BU35: 0 | BV35: 0 | BW35: 0 | BX35: 0 | BY35: 0 | BZ35: 0 | CA35: CE | CB35: Varejo | CC35: Vendedor/Varejo | CD35: -4094675 | CE35: -39056715 | CF35: 3 | CG35: 3 - Meses | CH35: 0 - S/COMPRA | CI35: 0 - <= 0
A36: F_Sobral | B36: 2465 | C36: Gonzarlen | D36: 995 | G36: CLIENTES | H36: C00976 | I36: COMERCIAL NB | J36: ANTONIA NUBIA BIER | K36: 15 | M36: 7 | N36: PEQUENO VAREJO | O36: C | P36: Y | Q36: Centro | R36: Itatira | S36: CE | T36: BR | U36: 45688 | X36: Ter | Y36: Q1 | AA36: Revenda | AB36: 21 dias | AC36: BLT-SOF | AD36: INTERIOR CE | AE36: 62725-000 | AF36: -4.6511293 | AG36: -39.6747671 | AH36: Sim | AI36: Não | AJ36: Sim | AK36: 2422.04 | AL36: 1200 | AM36: 0 | AN36: 0 | AO36: 0 | AP36: 0 | AQ36: 0 | AR36: 0 | AS36: 0 | AT36: 0 | AU36: 0 | AV36: 0 | AW36: 0 | AX36: 1 | AY36: 1 | AZ36: 1 | BA36: 1 | BV36: 0 | BW36: 0 | BX36: 0 | BY36: 0 | BZ36: 0 | CA36: CE | CB36: Varejo | CC36: Vendedor/Varejo | CD36: -46511293 | CE36: -39674767 | CF36: 3 | CG36: 3 - Meses | CH36: 0 - S/COMPRA | CI36: 0 - <= 0
A37: M_Nacionais | B37: 12 | C37: Nacionais Cap | D37: 998 | G37: PAO DE ACUCAR CE | H37: C00983 | I37: PAO DE ACUCAR (SHOPPING ALDEOTA) | J37: CIA BRASILEIRA DE DISTRIBUICAO | K37: 2 | M37: 2 | N37: AUTOSSERVIÇO NACIONAL | O37: C | P37: Y | Q37: Meireles | R37: Fortaleza | S37: CE | T37: BR | U37: 45688 | X37: Seg | Y37: Semanal | Z37: 18 | AA37: Revenda | AB37: 60 dias | AC37: DEPOSITO | AD37: AUTOSSERVIÇO CE | AE37: 60160-230 | AF37: -3.7338948 | AG37: -38.496815 | AH37: Não | AI37: Não | AJ37: Não | AK37: 0 | AL37: 20000 | AM37: 0 | AN37: 0 | AO37: 0 | AP37: 0 | AQ37: 0 | AR37: 0 | AS37: 0 | AT37: 0 | AU37: 0 | AV37: 0 | AW37: 0 | AX37: 1 | AY37: 1 | AZ37: 1 | BA37: 1 | BV37: 0 | BW37: 0 | BX37: 0 | BY37: 0 | BZ37: 0 | CA37: CE | CB37: AS | CC37: Promotor | CD37: -37338948 | CE37: -38496815 | CF37: 3 | CG37: 3 - Meses | CH37: 0 - S/COMPRA | CI37: 0 - <= 0
A38: M_Capital | B38: 1441 | C38: Francineudo | D38: 1013 | G38: CLIENTES | H38: C01008 | I38: MERCADINHO FAMILIA (PINDORETAMA) | J38: MARIA LAURIENE CRUZ SILVA ME | K38: 15 | M38: 7 | N38: PEQUENO VAREJO | O38: C | P38: Y | Q38: Centro | R38: Pindoretama | S38: CE | T38: BR | U38: 45688 | X38: Ter | Y38: Semanal | AA38: Revenda | AB38: 21 dias | AC38: SMARTCOB | AD38: INTERIOR CE | AE38: 62860-000 | AF38: -4.0307411 | AG38: -38.3028113 | AH38: Sim | AI38: Não | AJ38: Sim | AK38: 0 | AL38: 800 | AM38: 0 | AN38: 0 | AO38: 0 | AP38: 0 | AQ38: 0 | AR38: 0 | AS38: 0 | AT38: 0 | AU38: 0 | AV38: 0 | AW38: 0 | AX38: 1 | AY38: 1 | AZ38: 1 | BA38: 1 | BV38: 0 | BW38: 0 | BX38: 0 | BY38: 0 | BZ38: 0 | CA38: CE | CB38: Varejo | CC38: Vendedor/Varejo | CD38: -40307411 | CE38: -38302811 | CF38: 3 | CG38: 3 - Meses | CH38: 0 - S/COMPRA | CI38: 0 - <= 0
A39: M_Capital | B39: 1441 | C39: Francineudo | D39: 1013 | G39: UNIREDE | H39: C01018 | I39: MERCADINHO E DEPOSITO MULTICASA | J39: ROZIMAR S DE CARVALHO ME | K39: 1 | M39: 1 | N39: AUTOSSERVIÇO REGIONAL | O39: C | P39: Y | Q39: Camurim | R39: Cascavel | S39: CE | T39: BR | U39: 45691 | X39: Seg | Y39: Q1 | AA39: Revenda | AB39: 15 dias | AC39: BLT-ITAÚ 130681 | AD39: INTERIOR CE | AE39: 62850-000 | AF39: -4.1328635 | AG39: -38.24709 | AH39: Sim | AI39: Sim | AJ39: Não | AK39: 0 | AL39: 350 | AM39: 1 | AN39: 0 | AO39: 1 | AP39: 0 | AQ39: 0 | AR39: 0 | AS39: 0 | AT39: 0 | AU39: 0 | AV39: 0 | AW39: 0 | AX39: 1 | AY39: 1 | AZ39: 1 | BA39: 1 | BB39: 0 | BC39: 0 | BD39: 0 | BE39: 0 | BV39: 0 | BW39: 0 | BX39: 0 | BY39: 0 | BZ39: 0 | CA39: CE | CB39: Varejo | CC39: Vendedor/Varejo | CD39: -41328635 | CE39: -3824709 | CF39: 3 | CG39: 3 - Meses | CH39: 0 - S/COMPRA | CI39: 0 - <= 0
A40: M_Nacionais | B40: 12 | C40: Franklin | D40: 1005 | G40: CLIENTES | H40: C01020 | I40: MERCADINHO SANTA TEREZINHA | J40: COMERCIAL DE ALIMENTOS SANTA TEREZINHA LTDA | K40: 1 | M40: 1 | N40: AUTOSSERVIÇO REGIONAL | O40: C | P40: Y | Q40: CENTRO | R40: PACAJUS | S40: CE | T40: BR | U40: 45688 | X40: Qua | Y40: Semanal | AA40: Revenda | AB40: 21 dias | AC40: BLT-SANT 804-1 | AD40: AUTOSSERVIÇO CE | AE40: 62870-000 | AF40: -4.174714 | AG40: -38.46939 | AH40: Sim | AI40: Não | AJ40: Não | AK40: 0 | AL40: 1500 | AM40: 0 | AN40: 0 | AO40: 0 | AP40: 0 | AQ40: 0 | AR40: 0 | AS40: 0 | AT40: 0 | AU40: 0 | AV40: 0 | AW40: 0 | AX40: 1 | AY40: 1 | AZ40: 1 | BA40: 1 | BV40: 0 | BW40: 0 | BX40: 0 | BY40: 0 | BZ40: 0 | CA40: CE | CB40: AS | CC40: Vendedor/AS | CD40: -4174714 | CE40: -3846939 | CF40: 3 | CG40: 3 - Meses | CH40: 0 - S/COMPRA | CI40: 0 - <= 0
...

Sheet Resumo Dia
A1: SC_3 meses Diário | B1: 46142
A2: Supervisor | B2: Manhã | C2: Tarde | D2: Diferença
A3: F_Juazeiro | B3: 10 | D3: =C3-B3 -> -10
A4: F_Maranhão | B4: 6 | D4: =C4-B4 -> -6
A5: F_Mossoró | B5: 16 | D5: =C5-B5 -> -16
A6: F_Sobral | B6: 63 | D6: =C6-B6 -> -63
A7: F_Teresina | B7: 33 | D7: =C7-B7 -> -33
A8: M_Capital | B8: 82 | D8: =C8-B8 -> -82
A9: M_Interior | B9: 9 | D9: =C9-B9 -> -9
A10: M_Nacionais | B10: 20 | D10: =C10-B10 -> -20
A11: M_Regionais | B11: 2 | D11: =C11-B11 -> -2
A12: F_Pernambuco_AS | B12: 1 | D12: =C12-B12 -> -1
A13: F_Pernambuco_PB | B13: 5 | D13: =C13-B13 -> -5
A14: F_Pernambuco_VA | B14: 9 | D14: =C14-B14 -> -9
... A16: Telemarketing | B16: 8 | D16: =C16-B16 -> -8
A17: Total Geral | B17: =SUM(B3:B16) -> 275 | C17: =SUM(C3:C16) -> 0 | D17: =B17-C17 -> 275

Sheet Analitico
A1: Supervisor | B1: Total Freezer | C1: Total freezer S/C | D1: % de Freezer S/C dentro de cada equipe | E1: % de participação de cada equipe no PROBLEMA TOTAL
A2: F_Juazeiro | B2: =_xlfn.XLOOKUP(A2,Fotografia!A:A,Fotografia!G:G) -> 240 | C2: 10 | D2: =C2/B2 -> 0.041666667 | E2: =C2/$C$16 -> 0.036363636
A3: F_Maranhão | B3: =_xlfn.XLOOKUP(A3,Fotografia!A:A,Fotografia!G:G) -> 125 | C3: 6 | D3: =C3/B3 -> 0.048 | E3: =C3/$C$16 -> 0.021818182
A4: F_Mossoró | B4: =_xlfn.XLOOKUP(A4,Fotografia!A:A,Fotografia!G:G) -> 57 | C4: 16 | D4: =C4/B4 -> 0.28070175 | E4: =C4/$C$16 -> 0.058181818
A5: F_Pernambuco_AS | B5: =_xlfn.XLOOKUP(A5,Fotografia!A:A,Fotografia!G:G) -> 23 | C5: 1 | D5: =C5/B5 -> 0.043478261 | E5: =C5/$C$16 -> 0.0036363636
A6: F_Pernambuco_PB | B6: =_xlfn.XLOOKUP(A6,Fotografia!A:A,Fotografia!G:G) -> 6 | C6: 5 | D6: =C6/B6 -> 0.83333333 | E6: =C6/$C$16 -> 0.018181818
A7: F_Pernambuco_VA | B7: =_xlfn.XLOOKUP(A7,Fotografia!A:A,Fotografia!G:G) -> 35 | C7: 9 | D7: =C7/B7 -> 0.25714286 | E7: =C7/$C$16 -> 0.032727273
A8: F_Sobral | B8: =_xlfn.XLOOKUP(A8,Fotografia!A:A,Fotografia!G:G) -> 684 | C8: 63 | D8: =C8/B8 -> 0.092105263 | E8: =C8/$C$16 -> 0.22909091
A9: F_Teresina | B9: =_xlfn.XLOOKUP(A9,Fotografia!A:A,Fotografia!G:G) -> 242 | C9: 33 | D9: =C9/B9 -> 0.13636364 | E9: =C9/$C$16 -> 0.12
A10: M_Capital | B10: =_xlfn.XLOOKUP(A10,Fotografia!A:A,Fotografia!G:G) -> 891 | C10: 82 | D10: =C10/B10 -> 0.092031425 | E10: =C10/$C$16 -> 0.29818182
A11: M_Interior | B11: =_xlfn.XLOOKUP(A11,Fotografia!A:A,Fotografia!G:G) -> 183 | C11: 9 | D11: =C11/B11 -> 0.049180328 | E11: =C11/$C$16 -> 0.032727273
A12: M_Nacionais | B12: =_xlfn.XLOOKUP(A12,Fotografia!A:A,Fotografia!G:G) -> 459 | C12: 20 | D12: =C12/B12 -> 0.043572985 | E12: =C12/$C$16 -> 0.072727273
A13: M_Regionais | B13: =_xlfn.XLOOKUP(A13,Fotografia!A:A,Fotografia!G:G) -> 341 | C13: 2 | D13: =C13/B13 -> 0.0058651026 | E13: =C13/$C$16 -> 0.0072727273
... A15: Telemarketing | B15: =_xlfn.XLOOKUP(A15,Fotografia!A:A,Fotografia!G:G) -> 218 | C15: 8 | D15: =C15/B15 -> 0.036697248 | E15: =C15/$C$16 -> 0.029090909
A16: Total | B16: =SUM(B2:B15) -> 3889 | C16: =SUM(C2:C15) -> 275 | D16: =C16/B16 -> 0.070712265 | E16: =C16/$C$16 -> 1
A18: Indicador GERAL (empresa) | B18: =C16/B16 -> 0.070712265
A19: Meta 3 M_SC | B19: 0.01
A20: Meta Mês | B20: 0.1
A22: 0.093
A23: 0.089
